<mujoco model="ufactory_uf850">
  <compiler angle="radian" meshdir="assets" autolimits="true"/>

  <option integrator="implicitfast"/>

  <default>
    <default class="uf850">
      <geom type="mesh"/>
      <joint axis="0 0 1" damping="1" armature="0.1"/>
      <position kp="2000" kv="200"/>
      <default class="size0">
        <position forcerange="-200 200"/>
      </default>
      <default class="size1">
        <position forcerange="-90 90"/>
      </default>
      <default class="size2">
        <position forcerange="-68 68"/>
      </default>
      <default class="size3">
        <position forcerange="-19 19"/>
      </default>
      <default class="visual">
        <geom contype="0" conaffinity="0" group="2" material="white"/>
      </default>
      <default class="collision">
        <geom group="3" mass="0" density="0"/>
      </default>
      <site size="0.001" rgba="0.5 0.5 0.5 0.3" group="4"/>
    </default>
  </default>

  <asset>
    <material name="white" rgba="1 1 1 1"/>
    <material name="silver" rgba=".753 .753 .753 1"/>

    <mesh file="visual/link_base.stl"/>
    <mesh file="visual/link1.stl"/>
    <mesh file="visual/link2.stl"/>
    <mesh file="visual/link3.stl"/>
    <mesh file="visual/link4.stl"/>
    <mesh file="visual/link5.stl"/>
    <mesh file="visual/link6.stl"/>
    <mesh name="link_base_c" file="collision/link_base.stl"/>
    <mesh name="link1_c" file="collision/link1.stl"/>
    <mesh name="link2_c" file="collision/link2.stl"/>
    <mesh name="link3_c" file="collision/link3.stl"/>
    <mesh name="link4_c" file="collision/link4.stl"/>
    <mesh name="link5_c" file="collision/link5.stl"/>
    <mesh name="link6_c" file="collision/link6.stl"/>
  </asset>

  <worldbody>
    <body name="link_base" pos="0 0 0.02570610177099758" childclass="uf850">
      <inertial pos="0 0 0" mass="4.0" diaginertia="0.0061063308908 0.0061063308908 0.01125"/>
      <geom class="visual" mesh="link_base"/>
      <geom name="link_base_c" class="collision" mesh="link_base_c"/>
      <body name="link1" pos="0 0 0.364">
        <inertial pos="5.7e-05 0.013842 -0.02055" quat="0.999624 -0.0273411 -0.000364635 -0.00185749" mass="4.807" diaginertia="0.0220018 0.0189206 0.0122503"/>
        <joint name="joint1" range="-6.28319 6.28319"/>
        <geom class="visual" mesh="link1"/>
        <geom name="link1_c" class="collision" mesh="link1_c"/>
        <body name="link2" quat="0.499998 0.5 -0.5 0.500002">
          <inertial pos="0.323425 9.5e-05 0.007586" quat="0.463878 0.532622 0.539126 0.458775" mass="3.28" diaginertia="0.0642088 0.0624144 0.00637301"/>
          <joint name="joint2" range="-2.30383 2.30383"/>
          <geom class="visual" mesh="link2"/>
          <geom name="link2_c" class="collision" mesh="link2_c"/>
          <body name="link3" pos="0.39 0 0" quat="-2.59734e-06 -0.707105 0.707108 2.59735e-06">
            <inertial pos="0.128834 0.11341 0.00978" quat="0.781477 0.318832 -0.496505 0.202789" mass="2.237" diaginertia="0.0155188 0.0144822 0.00312732"/>
            <joint name="joint3" range="-4.2237 0.061087"/>
            <geom class="visual" mesh="link3"/>
            <geom name="link3_c" class="collision" mesh="link3_c"/>
            <body name="link4" pos="0.15 0.426 0" quat="0.707105 -0.707108 0 0">
              <inertial pos="0.000266 -0.03833 -0.101915" quat="0.983546 0.180625 -0.00118669 -0.00323727" mass="2.041" diaginertia="0.0199188 0.0197497 0.00204912"/>
              <joint name="joint4" range="-6.28319 6.28319"/>
              <geom class="visual" mesh="link4"/>
              <geom name="link4_c" class="collision" mesh="link4_c"/>
              <body name="link5" quat="0.707105 -0.707108 0 0">
                <inertial pos="5.7e-05 -0.015267 -0.001015" quat="0.709629 0.704516 0.00436677 -0.00807823" mass="1.385" diaginertia="0.00207749 0.00203574 0.00110911"/>
                <joint name="joint5" range="-2.1642 2.1642"/>
                <geom class="visual" mesh="link5"/>
                <geom name="link5_c" class="collision" mesh="link5_c"/>
                <body name="link6" pos="0 -0.09 0" quat="0.707105 0.707108 0 0">
                  <inertial pos="0.000484 -0.000334 -0.014217" quat="0.63763 0.308332 -0.636717 0.30488" mass="0.225" diaginertia="0.000232503 0.000133671 0.000124886"/>
                  <joint name="joint6" range="-6.28319 6.28319"/>
                  <geom class="visual" mesh="link6" material="silver"/>
                  <geom name="link6_c" class="collision" mesh="link6_c"/>
                  <site name="attachment_site"/>
                </body>
              </body>
            </body>
          </body>
        </body>
      </body>
    </body>
  </worldbody>

  <actuator>
    <position name="joint1" joint="joint1" class="size0"/>
    <position name="joint2" joint="joint2" class="size0"/>
    <position name="joint3" joint="joint3" class="size1"/>
    <position name="joint4" joint="joint4" class="size2"/>
    <position name="joint5" joint="joint5" class="size3"/>
    <position name="joint6" joint="joint6" class="size3"/>
  </actuator>

  <keyframe>
    <key name="home" qpos="-1.5708 -1.5708 1.5708 -1.5708 -1.5708 0" ctrl="-1.5708 -1.5708 1.5708 -1.5708 -1.5708 0"/>
  </keyframe>
</mujoco>
