<mujoco model="ur30">
  <compiler angle="radian" meshdir="../universal_robots_ur30/assets" autolimits="true"/>
  <option integrator="implicitfast"/>

  <default>
    <include file="../universal_robots_ur30/ur30_classes.xml"/>
  </default>

  <asset>
    <include file="../universal_robots_ur30/ur30_assets.xml" />
  </asset>

  <worldbody>
    <light name="spotlight" mode="targetbodycom" target="wrist_2_link" pos="0 -1 2"/>
    <body name="ur30_base" pos="0.8 0.6 0.745" quat="1 0 0 0" childclass="ur30">
      <inertial mass="4.0" pos="0 0 0" diaginertia="0.00443333156 0.00443333156 0.0072"/>
      <!-- fix duplicate definition, add base_0 -->
      <geom mesh="base_0" material="black" class="visual"/>
      <geom mesh="base_1" material="black" class="visual"/>
      <geom mesh="base_2" material="black" class="visual"/>
      <geom mesh="base_3" material="black" class="visual"/>
      <geom mesh="base_4" material="jointgray" class="visual"/>
      <geom mesh="base_5" material="jointgray" class="visual"/>
      <geom mesh="base_6" material="jointgray" class="visual"/>
      <!-- add collision geometry -->
      <geom class="collision" size="0.078 0.08" pos="0 0 -0.05"/>

      <body name="shoulder_link" pos="0 0 0.2363">
        <inertial pos="0 0 0" mass="16.343" diaginertia="0.0102675 0.0102675 0.00666" />
        <joint name="shoulder_pan_joint" class="size4" axis="0 0 1"/>
        <geom mesh="shoulder_0" material="urblue" class="visual"/>
        <geom mesh="shoulder_1" material="black" class="visual"/>
        <geom mesh="shoulder_2" material="jointgray" class="visual"/>
        <!-- add collision geometry -->
        <geom class="collision" size="0.078 0.08" pos="0 0 -0.05"/>
      
        <body name="upper_arm_link" pos="0 0.2629 0" quat="1 0 0 0">
          <inertial pos="0 0 -0.3185" mass="28.542" diaginertia="0.133886 0.133886 0.0151074" />
          <joint name="shoulder_lift_joint" class="size4"/>
          <geom mesh="upperarm_0" material="jointgray" class="visual"/>
          <geom mesh="upperarm_1" material="jointgray" class="visual"/>
          <geom mesh="upperarm_2" material="urblue" class="visual"/>
          <geom mesh="upperarm_3" material="black" class="visual"/>
          <geom mesh="upperarm_4" material="jointgray" class="visual"/>
          <geom mesh="upperarm_5" material="linkgray" class="visual"/>
          <!-- add collision geometry -->
          <geom class="collision" pos="0 -0.05 0" quat="1 1 0 0" size="0.078 0.08"/>
          <geom class="collision" size="0.06 0.3" pos="0 0 0.3"/>
       
          <body name="forearm_link" pos="0 -0.2197 0.637">
            <inertial pos="0 0 -0.25185" mass="7.156" diaginertia="0.0311796 0.0311796 0.004095" />
            <joint name="elbow_joint" class="size3_limited"/>
            <geom mesh="forearm_0" material="urblue" class="visual"/>
            <geom mesh="forearm_1" material="linkgray" class="visual"/>
            <geom mesh="forearm_2" material="urblue" class="visual"/>
            <geom mesh="forearm_3" material="urblue" class="visual"/>
            <geom mesh="forearm_4" material="jointgray" class="visual"/>
            <geom mesh="forearm_5" material="urblue" class="visual"/>
            <geom mesh="forearm_6" material="black" class="visual"/>
            <!-- add collision geometry -->
            <geom class="collision" pos="0 0.08 0" quat="1 1 0 0" size="0.058 0.065"/>
            <geom class="collision" size="0.043 0.28" pos="0 0 0.29"/>
         
            <body name="wrist_1_link" pos="0 0 0.5037" quat="1 0 0 0">
              <inertial pos="0 0.1578 0" quat="0.5 0.5 -0.5 0.5" mass="3.054" diaginertia="0.0025599 0.0025599 0.0021942" />
              <joint name="wrist_1_joint" class="size2"/>
              <geom mesh="wrist1_0" material="black" class="visual"/>
              <geom mesh="wrist1_1" material="black" class="visual"/>
              <geom mesh="wrist1_2" material="jointgray" class="visual"/>
              <geom mesh="wrist1_3" material="jointgray" class="visual"/>
              <geom mesh="wrist1_4" material="urblue" class="visual"/>
              <!-- add collision geometry -->
              <geom class="collision" pos="0 0.06 0" quat="1 1 0 0" size="0.05 0.07"/>
           
              <body name="wrist_2_link" pos="0 0.1578 0">
                <inertial pos="0 0 0.1593" quat="0.5 0.5 -0.5 0.5" mass="3.126" diaginertia="0.0025599 0.0025599 0.0021942" />
                <joint name="wrist_2_joint" class="size2" axis="0 0 1"/>
                <geom mesh="wrist2_0" material="black" class="visual"/>
                <geom mesh="wrist2_1" material="black" class="visual"/>
                <geom mesh="wrist2_2" material="jointgray" class="visual"/>
                <geom mesh="wrist2_3" material="jointgray" class="visual"/>
                <geom mesh="wrist2_4" material="jointgray" class="visual"/>
                <geom mesh="wrist2_5" material="jointgray" class="visual"/>
                <!-- 添加碰撞几何体 -->
                <geom class="collision" size="0.046 0.065" pos="0 0 0.05"/>
                <geom class="collision" pos="0 0.028 0.12" quat="1 1 0 0" size="0.046 0.043"/>
              
                <body name="wrist_3_link" pos="0 0 0.1593">
                  <inertial pos="0 0.129316 0" quat="0.5 0.5 -0.5 0.5" mass="0.927" diaginertia="0.000132134 9.90863e-05 9.90863e-05" />
                  <joint name="wrist_3_joint" class="size2"/>
                  <geom mesh="wrist3_0" material="linkgray" class="visual"/>
                  <geom mesh="wrist3_1" material="linkgray" class="visual"/>
                  <geom mesh="wrist3_2" material="linkgray" class="visual"/>
                  <geom mesh="wrist3_3" material="linkgray" class="visual"/>
                  <geom mesh="wrist3_4" material="linkgray" class="visual"/>
                  <!-- 添加碰撞几何体 -->
                  <geom class="eef_collision" pos="0 0.097 0" quat="1 1 0 0" size="0.046 0.02"/>
                  <site name="attachment_site" pos="0 0.1 0" quat="-1 1 0 0"/>
                  
                  <!-- 添加手部相机，参考UR5e -->
                  <camera name="hand_camera" pos="0 0.1 0.2" xyaxes="-1 0 0 0 -1 -1" mode="fixed"/>
                  
                  <!-- 添加flange身体用于夹爪连接 -->
                  <body name="flange" pos="0 0.1 0" quat="1 -1 0 0">
                    <site name="tcp" pos="0 0 0" size="0.01" rgba="0 1 0 0.5" group="2" />
                  </body>
                </body>
              </body>
            </body>
          </body>
        </body>
      </body>
    </body>
  </worldbody>

  <actuator>
    <general class="size4" name="shoulder_pan" joint="shoulder_pan_joint"/>
    <general class="size4" name="shoulder_lift" joint="shoulder_lift_joint"/>
    <general class="size3_limited" name="elbow" joint="elbow_joint"/>
    <general class="size2" name="wrist_1" joint="wrist_1_joint"/>
    <general class="size2" name="wrist_2" joint="wrist_2_joint"/>
    <general class="size2" name="wrist_3" joint="wrist_3_joint"/>
  </actuator>
  
  <!-- 暂时注释掉关键帧，避免关节数量不匹配 -->
  <!--
  <keyframe>
    <key name="home" qpos="-1.5708 -1.5708 1.5708 -1.5708 -1.5708 0" ctrl="-1.5708 -1.5708 1.5708 -1.5708 -1.5708 0"/>
  </keyframe>
  -->
</mujoco>
